2021-06-10 11:33:09,146 [ERROR] django.request: Internal Server Error: /search
Traceback (most recent call last):
  File "C:\Users\Zhixuan\AppData\Local\Programs\Python\Python39\lib\site-packages\django\core\handlers\exception.py", line 47, in inner
    response = get_response(request)
  File "C:\Users\Zhixuan\AppData\Local\Programs\Python\Python39\lib\site-packages\django\utils\deprecation.py", line 119, in __call__
    response = self.process_response(request, response)
  File "C:\Users\Zhixuan\AppData\Local\Programs\Python\Python39\lib\site-packages\django\middleware\clickjacking.py", line 26, in process_response
    if response.get('X-Frame-Options') is not None:
AttributeError: 'tuple' object has no attribute 'get'
2021-06-10 11:37:02,282 [ERROR] django.request: Internal Server Error: /search
Traceback (most recent call last):
  File "C:\Users\Zhixuan\AppData\Local\Programs\Python\Python39\lib\site-packages\django\db\models\fields\__init__.py", line 1823, in get_prep_value
    return int(value)
ValueError: invalid literal for int() with base 10: ''

The above exception was the direct cause of the following exception:

Traceback (most recent call last):
  File "C:\Users\Zhixuan\AppData\Local\Programs\Python\Python39\lib\site-packages\django\core\handlers\exception.py", line 47, in inner
    response = get_response(request)
  File "C:\Users\Zhixuan\AppData\Local\Programs\Python\Python39\lib\site-packages\django\core\handlers\base.py", line 181, in _get_response
    response = wrapped_callback(request, *callback_args, **callback_kwargs)
  File "C:\Users\Zhixuan\Documents\GitHub\savethehawkers\project\views.py", line 116, in search
    place = Zipcode.objects.filter(postal = postalcode)
  File "C:\Users\Zhixuan\AppData\Local\Programs\Python\Python39\lib\site-packages\django\db\models\manager.py", line 85, in manager_method
    return getattr(self.get_queryset(), name)(*args, **kwargs)
  File "C:\Users\Zhixuan\AppData\Local\Programs\Python\Python39\lib\site-packages\django\db\models\query.py", line 941, in filter
    return self._filter_or_exclude(False, args, kwargs)
  File "C:\Users\Zhixuan\AppData\Local\Programs\Python\Python39\lib\site-packages\django\db\models\query.py", line 961, in _filter_or_exclude
    clone._filter_or_exclude_inplace(negate, args, kwargs)
  File "C:\Users\Zhixuan\AppData\Local\Programs\Python\Python39\lib\site-packages\django\db\models\query.py", line 968, in _filter_or_exclude_inplace
    self._query.add_q(Q(*args, **kwargs))
  File "C:\Users\Zhixuan\AppData\Local\Programs\Python\Python39\lib\site-packages\django\db\models\sql\query.py", line 1391, in add_q
    clause, _ = self._add_q(q_object, self.used_aliases)
  File "C:\Users\Zhixuan\AppData\Local\Programs\Python\Python39\lib\site-packages\django\db\models\sql\query.py", line 1410, in _add_q
    child_clause, needed_inner = self.build_filter(
  File "C:\Users\Zhixuan\AppData\Local\Programs\Python\Python39\lib\site-packages\django\db\models\sql\query.py", line 1345, in build_filter
    condition = self.build_lookup(lookups, col, value)
  File "C:\Users\Zhixuan\AppData\Local\Programs\Python\Python39\lib\site-packages\django\db\models\sql\query.py", line 1191, in build_lookup
    lookup = lookup_class(lhs, rhs)
  File "C:\Users\Zhixuan\AppData\Local\Programs\Python\Python39\lib\site-packages\django\db\models\lookups.py", line 25, in __init__
    self.rhs = self.get_prep_lookup()
  File "C:\Users\Zhixuan\AppData\Local\Programs\Python\Python39\lib\site-packages\django\db\models\lookups.py", line 77, in get_prep_lookup
    return self.lhs.output_field.get_prep_value(self.rhs)
  File "C:\Users\Zhixuan\AppData\Local\Programs\Python\Python39\lib\site-packages\django\db\models\fields\__init__.py", line 1825, in get_prep_value
    raise e.__class__(
ValueError: Field 'postal' expected a number but got ''.
2021-06-10 11:37:33,073 [ERROR] django.request: Internal Server Error: /search
Traceback (most recent call last):
  File "C:\Users\Zhixuan\AppData\Local\Programs\Python\Python39\lib\site-packages\django\db\models\fields\__init__.py", line 1823, in get_prep_value
    return int(value)
ValueError: invalid literal for int() with base 10: ''

The above exception was the direct cause of the following exception:

Traceback (most recent call last):
  File "C:\Users\Zhixuan\AppData\Local\Programs\Python\Python39\lib\site-packages\django\core\handlers\exception.py", line 47, in inner
    response = get_response(request)
  File "C:\Users\Zhixuan\AppData\Local\Programs\Python\Python39\lib\site-packages\django\core\handlers\base.py", line 181, in _get_response
    response = wrapped_callback(request, *callback_args, **callback_kwargs)
  File "C:\Users\Zhixuan\Documents\GitHub\savethehawkers\project\views.py", line 122, in search
    place = Zipcode.objects.filter(postal = postalcode)
  File "C:\Users\Zhixuan\AppData\Local\Programs\Python\Python39\lib\site-packages\django\db\models\manager.py", line 85, in manager_method
    return getattr(self.get_queryset(), name)(*args, **kwargs)
  File "C:\Users\Zhixuan\AppData\Local\Programs\Python\Python39\lib\site-packages\django\db\models\query.py", line 941, in filter
    return self._filter_or_exclude(False, args, kwargs)
  File "C:\Users\Zhixuan\AppData\Local\Programs\Python\Python39\lib\site-packages\django\db\models\query.py", line 961, in _filter_or_exclude
    clone._filter_or_exclude_inplace(negate, args, kwargs)
  File "C:\Users\Zhixuan\AppData\Local\Programs\Python\Python39\lib\site-packages\django\db\models\query.py", line 968, in _filter_or_exclude_inplace
    self._query.add_q(Q(*args, **kwargs))
  File "C:\Users\Zhixuan\AppData\Local\Programs\Python\Python39\lib\site-packages\django\db\models\sql\query.py", line 1391, in add_q
    clause, _ = self._add_q(q_object, self.used_aliases)
  File "C:\Users\Zhixuan\AppData\Local\Programs\Python\Python39\lib\site-packages\django\db\models\sql\query.py", line 1410, in _add_q
    child_clause, needed_inner = self.build_filter(
  File "C:\Users\Zhixuan\AppData\Local\Programs\Python\Python39\lib\site-packages\django\db\models\sql\query.py", line 1345, in build_filter
    condition = self.build_lookup(lookups, col, value)
  File "C:\Users\Zhixuan\AppData\Local\Programs\Python\Python39\lib\site-packages\django\db\models\sql\query.py", line 1191, in build_lookup
    lookup = lookup_class(lhs, rhs)
  File "C:\Users\Zhixuan\AppData\Local\Programs\Python\Python39\lib\site-packages\django\db\models\lookups.py", line 25, in __init__
    self.rhs = self.get_prep_lookup()
  File "C:\Users\Zhixuan\AppData\Local\Programs\Python\Python39\lib\site-packages\django\db\models\lookups.py", line 77, in get_prep_lookup
    return self.lhs.output_field.get_prep_value(self.rhs)
  File "C:\Users\Zhixuan\AppData\Local\Programs\Python\Python39\lib\site-packages\django\db\models\fields\__init__.py", line 1825, in get_prep_value
    raise e.__class__(
ValueError: Field 'postal' expected a number but got ''.
2021-06-10 11:37:35,932 [ERROR] django.request: Internal Server Error: /search
Traceback (most recent call last):
  File "C:\Users\Zhixuan\AppData\Local\Programs\Python\Python39\lib\site-packages\django\db\models\fields\__init__.py", line 1823, in get_prep_value
    return int(value)
ValueError: invalid literal for int() with base 10: ''

The above exception was the direct cause of the following exception:

Traceback (most recent call last):
  File "C:\Users\Zhixuan\AppData\Local\Programs\Python\Python39\lib\site-packages\django\core\handlers\exception.py", line 47, in inner
    response = get_response(request)
  File "C:\Users\Zhixuan\AppData\Local\Programs\Python\Python39\lib\site-packages\django\core\handlers\base.py", line 181, in _get_response
    response = wrapped_callback(request, *callback_args, **callback_kwargs)
  File "C:\Users\Zhixuan\Documents\GitHub\savethehawkers\project\views.py", line 122, in search
    place = Zipcode.objects.filter(postal = postalcode)
  File "C:\Users\Zhixuan\AppData\Local\Programs\Python\Python39\lib\site-packages\django\db\models\manager.py", line 85, in manager_method
    return getattr(self.get_queryset(), name)(*args, **kwargs)
  File "C:\Users\Zhixuan\AppData\Local\Programs\Python\Python39\lib\site-packages\django\db\models\query.py", line 941, in filter
    return self._filter_or_exclude(False, args, kwargs)
  File "C:\Users\Zhixuan\AppData\Local\Programs\Python\Python39\lib\site-packages\django\db\models\query.py", line 961, in _filter_or_exclude
    clone._filter_or_exclude_inplace(negate, args, kwargs)
  File "C:\Users\Zhixuan\AppData\Local\Programs\Python\Python39\lib\site-packages\django\db\models\query.py", line 968, in _filter_or_exclude_inplace
    self._query.add_q(Q(*args, **kwargs))
  File "C:\Users\Zhixuan\AppData\Local\Programs\Python\Python39\lib\site-packages\django\db\models\sql\query.py", line 1391, in add_q
    clause, _ = self._add_q(q_object, self.used_aliases)
  File "C:\Users\Zhixuan\AppData\Local\Programs\Python\Python39\lib\site-packages\django\db\models\sql\query.py", line 1410, in _add_q
    child_clause, needed_inner = self.build_filter(
  File "C:\Users\Zhixuan\AppData\Local\Programs\Python\Python39\lib\site-packages\django\db\models\sql\query.py", line 1345, in build_filter
    condition = self.build_lookup(lookups, col, value)
  File "C:\Users\Zhixuan\AppData\Local\Programs\Python\Python39\lib\site-packages\django\db\models\sql\query.py", line 1191, in build_lookup
    lookup = lookup_class(lhs, rhs)
  File "C:\Users\Zhixuan\AppData\Local\Programs\Python\Python39\lib\site-packages\django\db\models\lookups.py", line 25, in __init__
    self.rhs = self.get_prep_lookup()
  File "C:\Users\Zhixuan\AppData\Local\Programs\Python\Python39\lib\site-packages\django\db\models\lookups.py", line 77, in get_prep_lookup
    return self.lhs.output_field.get_prep_value(self.rhs)
  File "C:\Users\Zhixuan\AppData\Local\Programs\Python\Python39\lib\site-packages\django\db\models\fields\__init__.py", line 1825, in get_prep_value
    raise e.__class__(
ValueError: Field 'postal' expected a number but got ''.
2021-06-10 11:38:00,364 [ERROR] django.request: Internal Server Error: /search
Traceback (most recent call last):
  File "C:\Users\Zhixuan\AppData\Local\Programs\Python\Python39\lib\site-packages\django\core\handlers\exception.py", line 47, in inner
    response = get_response(request)
  File "C:\Users\Zhixuan\AppData\Local\Programs\Python\Python39\lib\site-packages\django\utils\deprecation.py", line 119, in __call__
    response = self.process_response(request, response)
  File "C:\Users\Zhixuan\AppData\Local\Programs\Python\Python39\lib\site-packages\django\middleware\clickjacking.py", line 26, in process_response
    if response.get('X-Frame-Options') is not None:
AttributeError: 'tuple' object has no attribute 'get'
2021-06-10 11:38:26,706 [ERROR] django.request: Internal Server Error: /search
Traceback (most recent call last):
  File "C:\Users\Zhixuan\AppData\Local\Programs\Python\Python39\lib\site-packages\django\core\handlers\exception.py", line 47, in inner
    response = get_response(request)
  File "C:\Users\Zhixuan\AppData\Local\Programs\Python\Python39\lib\site-packages\django\utils\deprecation.py", line 119, in __call__
    response = self.process_response(request, response)
  File "C:\Users\Zhixuan\AppData\Local\Programs\Python\Python39\lib\site-packages\django\middleware\clickjacking.py", line 26, in process_response
    if response.get('X-Frame-Options') is not None:
AttributeError: 'tuple' object has no attribute 'get'
2021-06-10 11:39:35,246 [ERROR] django.request: Internal Server Error: /search
Traceback (most recent call last):
  File "C:\Users\Zhixuan\AppData\Local\Programs\Python\Python39\lib\site-packages\django\core\handlers\exception.py", line 47, in inner
    response = get_response(request)
  File "C:\Users\Zhixuan\AppData\Local\Programs\Python\Python39\lib\site-packages\django\utils\deprecation.py", line 119, in __call__
    response = self.process_response(request, response)
  File "C:\Users\Zhixuan\AppData\Local\Programs\Python\Python39\lib\site-packages\django\middleware\clickjacking.py", line 26, in process_response
    if response.get('X-Frame-Options') is not None:
AttributeError: 'tuple' object has no attribute 'get'
2021-06-10 11:49:17,581 [ERROR] django.request: Internal Server Error: /search
Traceback (most recent call last):
  File "C:\Users\Zhixuan\AppData\Local\Programs\Python\Python39\lib\site-packages\django\core\handlers\exception.py", line 47, in inner
    response = get_response(request)
  File "C:\Users\Zhixuan\AppData\Local\Programs\Python\Python39\lib\site-packages\django\core\handlers\base.py", line 181, in _get_response
    response = wrapped_callback(request, *callback_args, **callback_kwargs)
  File "C:\Users\Zhixuan\Documents\GitHub\savethehawkers\project\views.py", line 125, in search
    latorigin = place.first().latitude
AttributeError: 'NoneType' object has no attribute 'latitude'
2021-06-10 13:17:29,526 [ERROR] django.request: Internal Server Error: /search
Traceback (most recent call last):
  File "C:\Users\Zhixuan\AppData\Local\Programs\Python\Python39\lib\site-packages\django\core\handlers\exception.py", line 47, in inner
    response = get_response(request)
  File "C:\Users\Zhixuan\AppData\Local\Programs\Python\Python39\lib\site-packages\django\utils\deprecation.py", line 119, in __call__
    response = self.process_response(request, response)
  File "C:\Users\Zhixuan\AppData\Local\Programs\Python\Python39\lib\site-packages\django\middleware\clickjacking.py", line 26, in process_response
    if response.get('X-Frame-Options') is not None:
AttributeError: 'tuple' object has no attribute 'get'
2021-06-10 13:17:34,891 [ERROR] django.request: Internal Server Error: /search
Traceback (most recent call last):
  File "C:\Users\Zhixuan\AppData\Local\Programs\Python\Python39\lib\site-packages\django\core\handlers\exception.py", line 47, in inner
    response = get_response(request)
  File "C:\Users\Zhixuan\AppData\Local\Programs\Python\Python39\lib\site-packages\django\utils\deprecation.py", line 119, in __call__
    response = self.process_response(request, response)
  File "C:\Users\Zhixuan\AppData\Local\Programs\Python\Python39\lib\site-packages\django\middleware\clickjacking.py", line 26, in process_response
    if response.get('X-Frame-Options') is not None:
AttributeError: 'tuple' object has no attribute 'get'
2021-06-10 13:19:36,288 [ERROR] django.request: Internal Server Error: /search
Traceback (most recent call last):
  File "C:\Users\Zhixuan\AppData\Local\Programs\Python\Python39\lib\site-packages\django\core\handlers\exception.py", line 47, in inner
    response = get_response(request)
  File "C:\Users\Zhixuan\AppData\Local\Programs\Python\Python39\lib\site-packages\django\utils\deprecation.py", line 119, in __call__
    response = self.process_response(request, response)
  File "C:\Users\Zhixuan\AppData\Local\Programs\Python\Python39\lib\site-packages\django\middleware\clickjacking.py", line 26, in process_response
    if response.get('X-Frame-Options') is not None:
AttributeError: 'tuple' object has no attribute 'get'
2021-06-10 13:19:47,961 [ERROR] django.request: Internal Server Error: /search
Traceback (most recent call last):
  File "C:\Users\Zhixuan\AppData\Local\Programs\Python\Python39\lib\site-packages\django\core\handlers\exception.py", line 47, in inner
    response = get_response(request)
  File "C:\Users\Zhixuan\AppData\Local\Programs\Python\Python39\lib\site-packages\django\utils\deprecation.py", line 119, in __call__
    response = self.process_response(request, response)
  File "C:\Users\Zhixuan\AppData\Local\Programs\Python\Python39\lib\site-packages\django\middleware\clickjacking.py", line 26, in process_response
    if response.get('X-Frame-Options') is not None:
AttributeError: 'tuple' object has no attribute 'get'
2021-06-10 13:21:21,585 [ERROR] django.request: Internal Server Error: /search
Traceback (most recent call last):
  File "C:\Users\Zhixuan\AppData\Local\Programs\Python\Python39\lib\site-packages\django\core\handlers\exception.py", line 47, in inner
    response = get_response(request)
  File "C:\Users\Zhixuan\AppData\Local\Programs\Python\Python39\lib\site-packages\django\utils\deprecation.py", line 119, in __call__
    response = self.process_response(request, response)
  File "C:\Users\Zhixuan\AppData\Local\Programs\Python\Python39\lib\site-packages\django\middleware\clickjacking.py", line 26, in process_response
    if response.get('X-Frame-Options') is not None:
AttributeError: 'tuple' object has no attribute 'get'
2021-06-10 14:09:13,234 [ERROR] django.request: Internal Server Error: /next
Traceback (most recent call last):
  File "C:\Users\Zhixuan\AppData\Local\Programs\Python\Python39\lib\site-packages\django\core\handlers\exception.py", line 47, in inner
    response = get_response(request)
  File "C:\Users\Zhixuan\AppData\Local\Programs\Python\Python39\lib\site-packages\django\core\handlers\base.py", line 181, in _get_response
    response = wrapped_callback(request, *callback_args, **callback_kwargs)
  File "C:\Users\Zhixuan\Documents\GitHub\savethehawkers\project\views.py", line 205, in next
    pagenumber += 1
TypeError: can only concatenate str (not "int") to str
2021-06-10 14:10:09,209 [ERROR] django.request: Internal Server Error: /next
Traceback (most recent call last):
  File "C:\Users\Zhixuan\AppData\Local\Programs\Python\Python39\lib\site-packages\django\core\handlers\exception.py", line 47, in inner
    response = get_response(request)
  File "C:\Users\Zhixuan\AppData\Local\Programs\Python\Python39\lib\site-packages\django\core\handlers\base.py", line 181, in _get_response
    response = wrapped_callback(request, *callback_args, **callback_kwargs)
  File "C:\Users\Zhixuan\Documents\GitHub\savethehawkers\project\views.py", line 277, in next
    "latandlong": latandlong[(6*(page-1)):],
TypeError: 'zip' object is not subscriptable
2021-06-10 14:10:57,580 [ERROR] django.request: Internal Server Error: /next
Traceback (most recent call last):
  File "C:\Users\Zhixuan\AppData\Local\Programs\Python\Python39\lib\site-packages\django\core\handlers\exception.py", line 47, in inner
    response = get_response(request)
  File "C:\Users\Zhixuan\AppData\Local\Programs\Python\Python39\lib\site-packages\django\core\handlers\base.py", line 181, in _get_response
    response = wrapped_callback(request, *callback_args, **callback_kwargs)
  File "C:\Users\Zhixuan\Documents\GitHub\savethehawkers\project\views.py", line 260, in next
    myhouselat = [latorigin] * len(results) - (6*(page-1))
TypeError: unsupported operand type(s) for -: 'list' and 'int'
2021-06-10 14:16:17,317 [ERROR] django.request: Internal Server Error: /search
Traceback (most recent call last):
  File "C:\Users\Zhixuan\AppData\Local\Programs\Python\Python39\lib\site-packages\django\core\handlers\exception.py", line 47, in inner
    response = get_response(request)
  File "C:\Users\Zhixuan\AppData\Local\Programs\Python\Python39\lib\site-packages\django\core\handlers\base.py", line 181, in _get_response
    response = wrapped_callback(request, *callback_args, **callback_kwargs)
  File "C:\Users\Zhixuan\Documents\GitHub\savethehawkers\project\views.py", line 182, in search
    return render(request, "project/search.html",{
  File "C:\Users\Zhixuan\AppData\Local\Programs\Python\Python39\lib\site-packages\django\shortcuts.py", line 19, in render
    content = loader.render_to_string(template_name, context, request, using=using)
  File "C:\Users\Zhixuan\AppData\Local\Programs\Python\Python39\lib\site-packages\django\template\loader.py", line 61, in render_to_string
    template = get_template(template_name, using=using)
  File "C:\Users\Zhixuan\AppData\Local\Programs\Python\Python39\lib\site-packages\django\template\loader.py", line 15, in get_template
    return engine.get_template(template_name)
  File "C:\Users\Zhixuan\AppData\Local\Programs\Python\Python39\lib\site-packages\django\template\backends\django.py", line 34, in get_template
    return Template(self.engine.get_template(template_name), self)
  File "C:\Users\Zhixuan\AppData\Local\Programs\Python\Python39\lib\site-packages\django\template\engine.py", line 143, in get_template
    template, origin = self.find_template(template_name)
  File "C:\Users\Zhixuan\AppData\Local\Programs\Python\Python39\lib\site-packages\django\template\engine.py", line 125, in find_template
    template = loader.get_template(name, skip=skip)
  File "C:\Users\Zhixuan\AppData\Local\Programs\Python\Python39\lib\site-packages\django\template\loaders\base.py", line 29, in get_template
    return Template(
  File "C:\Users\Zhixuan\AppData\Local\Programs\Python\Python39\lib\site-packages\django\template\base.py", line 155, in __init__
    self.nodelist = self.compile_nodelist()
  File "C:\Users\Zhixuan\AppData\Local\Programs\Python\Python39\lib\site-packages\django\template\base.py", line 193, in compile_nodelist
    return parser.parse()
  File "C:\Users\Zhixuan\AppData\Local\Programs\Python\Python39\lib\site-packages\django\template\base.py", line 478, in parse
    raise self.error(token, e)
  File "C:\Users\Zhixuan\AppData\Local\Programs\Python\Python39\lib\site-packages\django\template\base.py", line 476, in parse
    compiled_result = compile_func(self, token)
  File "C:\Users\Zhixuan\AppData\Local\Programs\Python\Python39\lib\site-packages\django\template\loader_tags.py", line 278, in do_extends
    nodelist = parser.parse()
  File "C:\Users\Zhixuan\AppData\Local\Programs\Python\Python39\lib\site-packages\django\template\base.py", line 478, in parse
    raise self.error(token, e)
  File "C:\Users\Zhixuan\AppData\Local\Programs\Python\Python39\lib\site-packages\django\template\base.py", line 476, in parse
    compiled_result = compile_func(self, token)
  File "C:\Users\Zhixuan\AppData\Local\Programs\Python\Python39\lib\site-packages\django\template\loader_tags.py", line 216, in do_block
    nodelist = parser.parse(('endblock',))
  File "C:\Users\Zhixuan\AppData\Local\Programs\Python\Python39\lib\site-packages\django\template\base.py", line 478, in parse
    raise self.error(token, e)
  File "C:\Users\Zhixuan\AppData\Local\Programs\Python\Python39\lib\site-packages\django\template\base.py", line 476, in parse
    compiled_result = compile_func(self, token)
  File "C:\Users\Zhixuan\AppData\Local\Programs\Python\Python39\lib\site-packages\django\template\defaulttags.py", line 1389, in url
    args.append(parser.compile_filter(value))
  File "C:\Users\Zhixuan\AppData\Local\Programs\Python\Python39\lib\site-packages\django\template\base.py", line 563, in compile_filter
    return FilterExpression(token, self)
  File "C:\Users\Zhixuan\AppData\Local\Programs\Python\Python39\lib\site-packages\django\template\base.py", line 662, in __init__
    raise TemplateSyntaxError("Could not parse the remainder: '%s' "
django.template.exceptions.TemplateSyntaxError: Could not parse the remainder: '{{pagenumber}}' from '{{pagenumber}}'
2021-06-10 14:21:08,173 [WARNING] django.request: Not Found: /1
2021-06-10 14:21:12,244 [WARNING] django.request: Not Found: /1
2021-06-10 14:24:20,251 [ERROR] django.request: Internal Server Error: /
Traceback (most recent call last):
  File "C:\Users\Zhixuan\AppData\Local\Programs\Python\Python39\lib\site-packages\django\core\handlers\exception.py", line 47, in inner
    response = get_response(request)
  File "C:\Users\Zhixuan\AppData\Local\Programs\Python\Python39\lib\site-packages\django\core\handlers\base.py", line 181, in _get_response
    response = wrapped_callback(request, *callback_args, **callback_kwargs)
  File "C:\Users\Zhixuan\Documents\GitHub\savethehawkers\project\views.py", line 105, in index
    return render(request, "project/index.html",{
  File "C:\Users\Zhixuan\AppData\Local\Programs\Python\Python39\lib\site-packages\django\shortcuts.py", line 19, in render
    content = loader.render_to_string(template_name, context, request, using=using)
  File "C:\Users\Zhixuan\AppData\Local\Programs\Python\Python39\lib\site-packages\django\template\loader.py", line 62, in render_to_string
    return template.render(context, request)
  File "C:\Users\Zhixuan\AppData\Local\Programs\Python\Python39\lib\site-packages\django\template\backends\django.py", line 61, in render
    return self.template.render(context)
  File "C:\Users\Zhixuan\AppData\Local\Programs\Python\Python39\lib\site-packages\django\template\base.py", line 170, in render
    return self._render(context)
  File "C:\Users\Zhixuan\AppData\Local\Programs\Python\Python39\lib\site-packages\django\template\base.py", line 162, in _render
    return self.nodelist.render(context)
  File "C:\Users\Zhixuan\AppData\Local\Programs\Python\Python39\lib\site-packages\django\template\base.py", line 938, in render
    bit = node.render_annotated(context)
  File "C:\Users\Zhixuan\AppData\Local\Programs\Python\Python39\lib\site-packages\django\template\base.py", line 905, in render_annotated
    return self.render(context)
  File "C:\Users\Zhixuan\AppData\Local\Programs\Python\Python39\lib\site-packages\django\template\loader_tags.py", line 150, in render
    return compiled_parent._render(context)
  File "C:\Users\Zhixuan\AppData\Local\Programs\Python\Python39\lib\site-packages\django\template\base.py", line 162, in _render
    return self.nodelist.render(context)
  File "C:\Users\Zhixuan\AppData\Local\Programs\Python\Python39\lib\site-packages\django\template\base.py", line 938, in render
    bit = node.render_annotated(context)
  File "C:\Users\Zhixuan\AppData\Local\Programs\Python\Python39\lib\site-packages\django\template\base.py", line 905, in render_annotated
    return self.render(context)
  File "C:\Users\Zhixuan\AppData\Local\Programs\Python\Python39\lib\site-packages\django\template\loader_tags.py", line 62, in render
    result = block.nodelist.render(context)
  File "C:\Users\Zhixuan\AppData\Local\Programs\Python\Python39\lib\site-packages\django\template\base.py", line 938, in render
    bit = node.render_annotated(context)
  File "C:\Users\Zhixuan\AppData\Local\Programs\Python\Python39\lib\site-packages\django\template\base.py", line 905, in render_annotated
    return self.render(context)
  File "C:\Users\Zhixuan\AppData\Local\Programs\Python\Python39\lib\site-packages\django\template\defaulttags.py", line 312, in render
    return nodelist.render(context)
  File "C:\Users\Zhixuan\AppData\Local\Programs\Python\Python39\lib\site-packages\django\template\base.py", line 938, in render
    bit = node.render_annotated(context)
  File "C:\Users\Zhixuan\AppData\Local\Programs\Python\Python39\lib\site-packages\django\template\base.py", line 905, in render_annotated
    return self.render(context)
  File "C:\Users\Zhixuan\AppData\Local\Programs\Python\Python39\lib\site-packages\django\template\defaulttags.py", line 446, in render
    url = reverse(view_name, args=args, kwargs=kwargs, current_app=current_app)
  File "C:\Users\Zhixuan\AppData\Local\Programs\Python\Python39\lib\site-packages\django\urls\base.py", line 86, in reverse
    return resolver._reverse_with_prefix(view, prefix, *args, **kwargs)
  File "C:\Users\Zhixuan\AppData\Local\Programs\Python\Python39\lib\site-packages\django\urls\resolvers.py", line 694, in _reverse_with_prefix
    raise NoReverseMatch(msg)
django.urls.exceptions.NoReverseMatch: Reverse for 'nextindex' not found. 'nextindex' is not a valid view function or pattern name.
2021-06-10 14:28:26,252 [ERROR] django.request: Internal Server Error: /1/next
Traceback (most recent call last):
  File "C:\Users\Zhixuan\AppData\Local\Programs\Python\Python39\lib\site-packages\django\db\models\fields\__init__.py", line 1823, in get_prep_value
    return int(value)
ValueError: invalid literal for int() with base 10: ''

The above exception was the direct cause of the following exception:

Traceback (most recent call last):
  File "C:\Users\Zhixuan\AppData\Local\Programs\Python\Python39\lib\site-packages\django\core\handlers\exception.py", line 47, in inner
    response = get_response(request)
  File "C:\Users\Zhixuan\AppData\Local\Programs\Python\Python39\lib\site-packages\django\core\handlers\base.py", line 181, in _get_response
    response = wrapped_callback(request, *callback_args, **callback_kwargs)
  File "C:\Users\Zhixuan\Documents\GitHub\savethehawkers\project\views.py", line 300, in next
    place = Zipcode.objects.filter(postal = postalcode)
  File "C:\Users\Zhixuan\AppData\Local\Programs\Python\Python39\lib\site-packages\django\db\models\manager.py", line 85, in manager_method
    return getattr(self.get_queryset(), name)(*args, **kwargs)
  File "C:\Users\Zhixuan\AppData\Local\Programs\Python\Python39\lib\site-packages\django\db\models\query.py", line 941, in filter
    return self._filter_or_exclude(False, args, kwargs)
  File "C:\Users\Zhixuan\AppData\Local\Programs\Python\Python39\lib\site-packages\django\db\models\query.py", line 961, in _filter_or_exclude
    clone._filter_or_exclude_inplace(negate, args, kwargs)
  File "C:\Users\Zhixuan\AppData\Local\Programs\Python\Python39\lib\site-packages\django\db\models\query.py", line 968, in _filter_or_exclude_inplace
    self._query.add_q(Q(*args, **kwargs))
  File "C:\Users\Zhixuan\AppData\Local\Programs\Python\Python39\lib\site-packages\django\db\models\sql\query.py", line 1391, in add_q
    clause, _ = self._add_q(q_object, self.used_aliases)
  File "C:\Users\Zhixuan\AppData\Local\Programs\Python\Python39\lib\site-packages\django\db\models\sql\query.py", line 1410, in _add_q
    child_clause, needed_inner = self.build_filter(
  File "C:\Users\Zhixuan\AppData\Local\Programs\Python\Python39\lib\site-packages\django\db\models\sql\query.py", line 1345, in build_filter
    condition = self.build_lookup(lookups, col, value)
  File "C:\Users\Zhixuan\AppData\Local\Programs\Python\Python39\lib\site-packages\django\db\models\sql\query.py", line 1191, in build_lookup
    lookup = lookup_class(lhs, rhs)
  File "C:\Users\Zhixuan\AppData\Local\Programs\Python\Python39\lib\site-packages\django\db\models\lookups.py", line 25, in __init__
    self.rhs = self.get_prep_lookup()
  File "C:\Users\Zhixuan\AppData\Local\Programs\Python\Python39\lib\site-packages\django\db\models\lookups.py", line 77, in get_prep_lookup
    return self.lhs.output_field.get_prep_value(self.rhs)
  File "C:\Users\Zhixuan\AppData\Local\Programs\Python\Python39\lib\site-packages\django\db\models\fields\__init__.py", line 1825, in get_prep_value
    raise e.__class__(
ValueError: Field 'postal' expected a number but got ''.
2021-06-10 14:29:04,447 [ERROR] django.request: Internal Server Error: /1/next
Traceback (most recent call last):
  File "C:\Users\Zhixuan\AppData\Local\Programs\Python\Python39\lib\site-packages\django\db\models\fields\__init__.py", line 1823, in get_prep_value
    return int(value)
ValueError: invalid literal for int() with base 10: ''

The above exception was the direct cause of the following exception:

Traceback (most recent call last):
  File "C:\Users\Zhixuan\AppData\Local\Programs\Python\Python39\lib\site-packages\django\core\handlers\exception.py", line 47, in inner
    response = get_response(request)
  File "C:\Users\Zhixuan\AppData\Local\Programs\Python\Python39\lib\site-packages\django\core\handlers\base.py", line 181, in _get_response
    response = wrapped_callback(request, *callback_args, **callback_kwargs)
  File "C:\Users\Zhixuan\Documents\GitHub\savethehawkers\project\views.py", line 301, in next
    place = Zipcode.objects.filter(postal = postalcode)
  File "C:\Users\Zhixuan\AppData\Local\Programs\Python\Python39\lib\site-packages\django\db\models\manager.py", line 85, in manager_method
    return getattr(self.get_queryset(), name)(*args, **kwargs)
  File "C:\Users\Zhixuan\AppData\Local\Programs\Python\Python39\lib\site-packages\django\db\models\query.py", line 941, in filter
    return self._filter_or_exclude(False, args, kwargs)
  File "C:\Users\Zhixuan\AppData\Local\Programs\Python\Python39\lib\site-packages\django\db\models\query.py", line 961, in _filter_or_exclude
    clone._filter_or_exclude_inplace(negate, args, kwargs)
  File "C:\Users\Zhixuan\AppData\Local\Programs\Python\Python39\lib\site-packages\django\db\models\query.py", line 968, in _filter_or_exclude_inplace
    self._query.add_q(Q(*args, **kwargs))
  File "C:\Users\Zhixuan\AppData\Local\Programs\Python\Python39\lib\site-packages\django\db\models\sql\query.py", line 1391, in add_q
    clause, _ = self._add_q(q_object, self.used_aliases)
  File "C:\Users\Zhixuan\AppData\Local\Programs\Python\Python39\lib\site-packages\django\db\models\sql\query.py", line 1410, in _add_q
    child_clause, needed_inner = self.build_filter(
  File "C:\Users\Zhixuan\AppData\Local\Programs\Python\Python39\lib\site-packages\django\db\models\sql\query.py", line 1345, in build_filter
    condition = self.build_lookup(lookups, col, value)
  File "C:\Users\Zhixuan\AppData\Local\Programs\Python\Python39\lib\site-packages\django\db\models\sql\query.py", line 1191, in build_lookup
    lookup = lookup_class(lhs, rhs)
  File "C:\Users\Zhixuan\AppData\Local\Programs\Python\Python39\lib\site-packages\django\db\models\lookups.py", line 25, in __init__
    self.rhs = self.get_prep_lookup()
  File "C:\Users\Zhixuan\AppData\Local\Programs\Python\Python39\lib\site-packages\django\db\models\lookups.py", line 77, in get_prep_lookup
    return self.lhs.output_field.get_prep_value(self.rhs)
  File "C:\Users\Zhixuan\AppData\Local\Programs\Python\Python39\lib\site-packages\django\db\models\fields\__init__.py", line 1825, in get_prep_value
    raise e.__class__(
ValueError: Field 'postal' expected a number but got ''.
2021-06-10 14:29:51,748 [ERROR] django.request: Internal Server Error: /1/next
Traceback (most recent call last):
  File "C:\Users\Zhixuan\AppData\Local\Programs\Python\Python39\lib\site-packages\django\db\models\fields\__init__.py", line 1823, in get_prep_value
    return int(value)
ValueError: invalid literal for int() with base 10: ''

The above exception was the direct cause of the following exception:

Traceback (most recent call last):
  File "C:\Users\Zhixuan\AppData\Local\Programs\Python\Python39\lib\site-packages\django\core\handlers\exception.py", line 47, in inner
    response = get_response(request)
  File "C:\Users\Zhixuan\AppData\Local\Programs\Python\Python39\lib\site-packages\django\core\handlers\base.py", line 181, in _get_response
    response = wrapped_callback(request, *callback_args, **callback_kwargs)
  File "C:\Users\Zhixuan\Documents\GitHub\savethehawkers\project\views.py", line 302, in next
    place = Zipcode.objects.filter(postal = postalcode)
  File "C:\Users\Zhixuan\AppData\Local\Programs\Python\Python39\lib\site-packages\django\db\models\manager.py", line 85, in manager_method
    return getattr(self.get_queryset(), name)(*args, **kwargs)
  File "C:\Users\Zhixuan\AppData\Local\Programs\Python\Python39\lib\site-packages\django\db\models\query.py", line 941, in filter
    return self._filter_or_exclude(False, args, kwargs)
  File "C:\Users\Zhixuan\AppData\Local\Programs\Python\Python39\lib\site-packages\django\db\models\query.py", line 961, in _filter_or_exclude
    clone._filter_or_exclude_inplace(negate, args, kwargs)
  File "C:\Users\Zhixuan\AppData\Local\Programs\Python\Python39\lib\site-packages\django\db\models\query.py", line 968, in _filter_or_exclude_inplace
    self._query.add_q(Q(*args, **kwargs))
  File "C:\Users\Zhixuan\AppData\Local\Programs\Python\Python39\lib\site-packages\django\db\models\sql\query.py", line 1391, in add_q
    clause, _ = self._add_q(q_object, self.used_aliases)
  File "C:\Users\Zhixuan\AppData\Local\Programs\Python\Python39\lib\site-packages\django\db\models\sql\query.py", line 1410, in _add_q
    child_clause, needed_inner = self.build_filter(
  File "C:\Users\Zhixuan\AppData\Local\Programs\Python\Python39\lib\site-packages\django\db\models\sql\query.py", line 1345, in build_filter
    condition = self.build_lookup(lookups, col, value)
  File "C:\Users\Zhixuan\AppData\Local\Programs\Python\Python39\lib\site-packages\django\db\models\sql\query.py", line 1191, in build_lookup
    lookup = lookup_class(lhs, rhs)
  File "C:\Users\Zhixuan\AppData\Local\Programs\Python\Python39\lib\site-packages\django\db\models\lookups.py", line 25, in __init__
    self.rhs = self.get_prep_lookup()
  File "C:\Users\Zhixuan\AppData\Local\Programs\Python\Python39\lib\site-packages\django\db\models\lookups.py", line 77, in get_prep_lookup
    return self.lhs.output_field.get_prep_value(self.rhs)
  File "C:\Users\Zhixuan\AppData\Local\Programs\Python\Python39\lib\site-packages\django\db\models\fields\__init__.py", line 1825, in get_prep_value
    raise e.__class__(
ValueError: Field 'postal' expected a number but got ''.
2021-06-10 14:29:59,815 [ERROR] django.request: Internal Server Error: /1/next
Traceback (most recent call last):
  File "C:\Users\Zhixuan\AppData\Local\Programs\Python\Python39\lib\site-packages\django\utils\datastructures.py", line 76, in __getitem__
    list_ = super().__getitem__(key)
KeyError: 'search'

During handling of the above exception, another exception occurred:

Traceback (most recent call last):
  File "C:\Users\Zhixuan\AppData\Local\Programs\Python\Python39\lib\site-packages\django\core\handlers\exception.py", line 47, in inner
    response = get_response(request)
  File "C:\Users\Zhixuan\AppData\Local\Programs\Python\Python39\lib\site-packages\django\core\handlers\base.py", line 181, in _get_response
    response = wrapped_callback(request, *callback_args, **callback_kwargs)
  File "C:\Users\Zhixuan\Documents\GitHub\savethehawkers\project\views.py", line 300, in next
    search = request.POST["search"]
  File "C:\Users\Zhixuan\AppData\Local\Programs\Python\Python39\lib\site-packages\django\utils\datastructures.py", line 78, in __getitem__
    raise MultiValueDictKeyError(key)
django.utils.datastructures.MultiValueDictKeyError: 'search'
2021-06-10 14:30:46,884 [ERROR] django.request: Internal Server Error: /1/next
Traceback (most recent call last):
  File "C:\Users\Zhixuan\AppData\Local\Programs\Python\Python39\lib\site-packages\django\utils\datastructures.py", line 76, in __getitem__
    list_ = super().__getitem__(key)
KeyError: 'search'

During handling of the above exception, another exception occurred:

Traceback (most recent call last):
  File "C:\Users\Zhixuan\AppData\Local\Programs\Python\Python39\lib\site-packages\django\core\handlers\exception.py", line 47, in inner
    response = get_response(request)
  File "C:\Users\Zhixuan\AppData\Local\Programs\Python\Python39\lib\site-packages\django\core\handlers\base.py", line 181, in _get_response
    response = wrapped_callback(request, *callback_args, **callback_kwargs)
  File "C:\Users\Zhixuan\Documents\GitHub\savethehawkers\project\views.py", line 299, in next
    search = request.POST["search"]
  File "C:\Users\Zhixuan\AppData\Local\Programs\Python\Python39\lib\site-packages\django\utils\datastructures.py", line 78, in __getitem__
    raise MultiValueDictKeyError(key)
django.utils.datastructures.MultiValueDictKeyError: 'search'
2021-06-10 14:30:49,366 [ERROR] django.request: Internal Server Error: /1/next
Traceback (most recent call last):
  File "C:\Users\Zhixuan\AppData\Local\Programs\Python\Python39\lib\site-packages\django\utils\datastructures.py", line 76, in __getitem__
    list_ = super().__getitem__(key)
KeyError: 'search'

During handling of the above exception, another exception occurred:

Traceback (most recent call last):
  File "C:\Users\Zhixuan\AppData\Local\Programs\Python\Python39\lib\site-packages\django\core\handlers\exception.py", line 47, in inner
    response = get_response(request)
  File "C:\Users\Zhixuan\AppData\Local\Programs\Python\Python39\lib\site-packages\django\core\handlers\base.py", line 181, in _get_response
    response = wrapped_callback(request, *callback_args, **callback_kwargs)
  File "C:\Users\Zhixuan\Documents\GitHub\savethehawkers\project\views.py", line 299, in next
    search = request.POST["search"]
  File "C:\Users\Zhixuan\AppData\Local\Programs\Python\Python39\lib\site-packages\django\utils\datastructures.py", line 78, in __getitem__
    raise MultiValueDictKeyError(key)
django.utils.datastructures.MultiValueDictKeyError: 'search'
2021-06-10 14:31:05,974 [ERROR] django.request: Internal Server Error: /1/nextin
Traceback (most recent call last):
  File "C:\Users\Zhixuan\AppData\Local\Programs\Python\Python39\lib\site-packages\django\core\handlers\exception.py", line 47, in inner
    response = get_response(request)
  File "C:\Users\Zhixuan\AppData\Local\Programs\Python\Python39\lib\site-packages\django\core\handlers\base.py", line 181, in _get_response
    response = wrapped_callback(request, *callback_args, **callback_kwargs)
  File "C:\Users\Zhixuan\Documents\GitHub\savethehawkers\project\views.py", line 208, in nextindex
    "latandlong": latandlong[(6*(page-1)):],
TypeError: 'zip' object is not subscriptable
2021-06-10 15:39:47,320 [ERROR] django.request: Internal Server Error: /
Traceback (most recent call last):
  File "C:\Users\Zhixuan\AppData\Local\Programs\Python\Python39\lib\site-packages\django\core\handlers\exception.py", line 47, in inner
    response = get_response(request)
  File "C:\Users\Zhixuan\AppData\Local\Programs\Python\Python39\lib\site-packages\django\core\handlers\base.py", line 181, in _get_response
    response = wrapped_callback(request, *callback_args, **callback_kwargs)
  File "C:\Users\Zhixuan\Documents\GitHub\savethehawkers\project\views.py", line 39, in index
    return render(request, "project/index.html",{
  File "C:\Users\Zhixuan\AppData\Local\Programs\Python\Python39\lib\site-packages\django\shortcuts.py", line 19, in render
    content = loader.render_to_string(template_name, context, request, using=using)
  File "C:\Users\Zhixuan\AppData\Local\Programs\Python\Python39\lib\site-packages\django\template\loader.py", line 62, in render_to_string
    return template.render(context, request)
  File "C:\Users\Zhixuan\AppData\Local\Programs\Python\Python39\lib\site-packages\django\template\backends\django.py", line 61, in render
    return self.template.render(context)
  File "C:\Users\Zhixuan\AppData\Local\Programs\Python\Python39\lib\site-packages\django\template\base.py", line 170, in render
    return self._render(context)
  File "C:\Users\Zhixuan\AppData\Local\Programs\Python\Python39\lib\site-packages\django\template\base.py", line 162, in _render
    return self.nodelist.render(context)
  File "C:\Users\Zhixuan\AppData\Local\Programs\Python\Python39\lib\site-packages\django\template\base.py", line 938, in render
    bit = node.render_annotated(context)
  File "C:\Users\Zhixuan\AppData\Local\Programs\Python\Python39\lib\site-packages\django\template\base.py", line 905, in render_annotated
    return self.render(context)
  File "C:\Users\Zhixuan\AppData\Local\Programs\Python\Python39\lib\site-packages\django\template\loader_tags.py", line 150, in render
    return compiled_parent._render(context)
  File "C:\Users\Zhixuan\AppData\Local\Programs\Python\Python39\lib\site-packages\django\template\base.py", line 162, in _render
    return self.nodelist.render(context)
  File "C:\Users\Zhixuan\AppData\Local\Programs\Python\Python39\lib\site-packages\django\template\base.py", line 938, in render
    bit = node.render_annotated(context)
  File "C:\Users\Zhixuan\AppData\Local\Programs\Python\Python39\lib\site-packages\django\template\base.py", line 905, in render_annotated
    return self.render(context)
  File "C:\Users\Zhixuan\AppData\Local\Programs\Python\Python39\lib\site-packages\django\template\loader_tags.py", line 62, in render
    result = block.nodelist.render(context)
  File "C:\Users\Zhixuan\AppData\Local\Programs\Python\Python39\lib\site-packages\django\template\base.py", line 938, in render
    bit = node.render_annotated(context)
  File "C:\Users\Zhixuan\AppData\Local\Programs\Python\Python39\lib\site-packages\django\template\base.py", line 905, in render_annotated
    return self.render(context)
  File "C:\Users\Zhixuan\AppData\Local\Programs\Python\Python39\lib\site-packages\django\template\defaulttags.py", line 312, in render
    return nodelist.render(context)
  File "C:\Users\Zhixuan\AppData\Local\Programs\Python\Python39\lib\site-packages\django\template\base.py", line 938, in render
    bit = node.render_annotated(context)
  File "C:\Users\Zhixuan\AppData\Local\Programs\Python\Python39\lib\site-packages\django\template\base.py", line 905, in render_annotated
    return self.render(context)
  File "C:\Users\Zhixuan\AppData\Local\Programs\Python\Python39\lib\site-packages\django\template\defaulttags.py", line 446, in render
    url = reverse(view_name, args=args, kwargs=kwargs, current_app=current_app)
  File "C:\Users\Zhixuan\AppData\Local\Programs\Python\Python39\lib\site-packages\django\urls\base.py", line 86, in reverse
    return resolver._reverse_with_prefix(view, prefix, *args, **kwargs)
  File "C:\Users\Zhixuan\AppData\Local\Programs\Python\Python39\lib\site-packages\django\urls\resolvers.py", line 694, in _reverse_with_prefix
    raise NoReverseMatch(msg)
django.urls.exceptions.NoReverseMatch: Reverse for 'nextindex' with arguments '('',)' not found. 1 pattern(s) tried: ['(?P<pagenumber>[0-9]+)/nextin$']
2021-06-10 15:39:50,211 [ERROR] django.request: Internal Server Error: /
Traceback (most recent call last):
  File "C:\Users\Zhixuan\AppData\Local\Programs\Python\Python39\lib\site-packages\django\core\handlers\exception.py", line 47, in inner
    response = get_response(request)
  File "C:\Users\Zhixuan\AppData\Local\Programs\Python\Python39\lib\site-packages\django\core\handlers\base.py", line 181, in _get_response
    response = wrapped_callback(request, *callback_args, **callback_kwargs)
  File "C:\Users\Zhixuan\Documents\GitHub\savethehawkers\project\views.py", line 92, in index
    ha = HawkerStall.objects.get(id = i)
  File "C:\Users\Zhixuan\AppData\Local\Programs\Python\Python39\lib\site-packages\django\db\models\manager.py", line 85, in manager_method
    return getattr(self.get_queryset(), name)(*args, **kwargs)
  File "C:\Users\Zhixuan\AppData\Local\Programs\Python\Python39\lib\site-packages\django\db\models\query.py", line 435, in get
    raise self.model.DoesNotExist(
project.models.HawkerStall.DoesNotExist: HawkerStall matching query does not exist.
2021-06-10 15:39:54,586 [ERROR] django.request: Internal Server Error: /
Traceback (most recent call last):
  File "C:\Users\Zhixuan\AppData\Local\Programs\Python\Python39\lib\site-packages\django\core\handlers\exception.py", line 47, in inner
    response = get_response(request)
  File "C:\Users\Zhixuan\AppData\Local\Programs\Python\Python39\lib\site-packages\django\core\handlers\base.py", line 181, in _get_response
    response = wrapped_callback(request, *callback_args, **callback_kwargs)
  File "C:\Users\Zhixuan\Documents\GitHub\savethehawkers\project\views.py", line 92, in index
    ha = HawkerStall.objects.get(id = i)
  File "C:\Users\Zhixuan\AppData\Local\Programs\Python\Python39\lib\site-packages\django\db\models\manager.py", line 85, in manager_method
    return getattr(self.get_queryset(), name)(*args, **kwargs)
  File "C:\Users\Zhixuan\AppData\Local\Programs\Python\Python39\lib\site-packages\django\db\models\query.py", line 435, in get
    raise self.model.DoesNotExist(
project.models.HawkerStall.DoesNotExist: HawkerStall matching query does not exist.
2021-06-10 15:41:10,355 [ERROR] django.request: Internal Server Error: /
Traceback (most recent call last):
  File "C:\Users\Zhixuan\AppData\Local\Programs\Python\Python39\lib\site-packages\django\core\handlers\exception.py", line 47, in inner
    response = get_response(request)
  File "C:\Users\Zhixuan\AppData\Local\Programs\Python\Python39\lib\site-packages\django\core\handlers\base.py", line 181, in _get_response
    response = wrapped_callback(request, *callback_args, **callback_kwargs)
  File "C:\Users\Zhixuan\Documents\GitHub\savethehawkers\project\views.py", line 92, in index
    ha = HawkerStall.objects.get(id = i)
  File "C:\Users\Zhixuan\AppData\Local\Programs\Python\Python39\lib\site-packages\django\db\models\manager.py", line 85, in manager_method
    return getattr(self.get_queryset(), name)(*args, **kwargs)
  File "C:\Users\Zhixuan\AppData\Local\Programs\Python\Python39\lib\site-packages\django\db\models\query.py", line 435, in get
    raise self.model.DoesNotExist(
project.models.HawkerStall.DoesNotExist: HawkerStall matching query does not exist.
2021-06-10 15:50:33,762 [ERROR] django.request: Internal Server Error: /stalltype
Traceback (most recent call last):
  File "C:\Users\Zhixuan\AppData\Local\Programs\Python\Python39\lib\site-packages\django\core\handlers\exception.py", line 47, in inner
    response = get_response(request)
  File "C:\Users\Zhixuan\AppData\Local\Programs\Python\Python39\lib\site-packages\django\core\handlers\base.py", line 181, in _get_response
    response = wrapped_callback(request, *callback_args, **callback_kwargs)
  File "C:\Users\Zhixuan\Documents\GitHub\savethehawkers\project\views.py", line 214, in stalltype
    return render(request, "project/index.html",{
  File "C:\Users\Zhixuan\AppData\Local\Programs\Python\Python39\lib\site-packages\django\shortcuts.py", line 19, in render
    content = loader.render_to_string(template_name, context, request, using=using)
  File "C:\Users\Zhixuan\AppData\Local\Programs\Python\Python39\lib\site-packages\django\template\loader.py", line 62, in render_to_string
    return template.render(context, request)
  File "C:\Users\Zhixuan\AppData\Local\Programs\Python\Python39\lib\site-packages\django\template\backends\django.py", line 61, in render
    return self.template.render(context)
  File "C:\Users\Zhixuan\AppData\Local\Programs\Python\Python39\lib\site-packages\django\template\base.py", line 170, in render
    return self._render(context)
  File "C:\Users\Zhixuan\AppData\Local\Programs\Python\Python39\lib\site-packages\django\template\base.py", line 162, in _render
    return self.nodelist.render(context)
  File "C:\Users\Zhixuan\AppData\Local\Programs\Python\Python39\lib\site-packages\django\template\base.py", line 938, in render
    bit = node.render_annotated(context)
  File "C:\Users\Zhixuan\AppData\Local\Programs\Python\Python39\lib\site-packages\django\template\base.py", line 905, in render_annotated
    return self.render(context)
  File "C:\Users\Zhixuan\AppData\Local\Programs\Python\Python39\lib\site-packages\django\template\loader_tags.py", line 150, in render
    return compiled_parent._render(context)
  File "C:\Users\Zhixuan\AppData\Local\Programs\Python\Python39\lib\site-packages\django\template\base.py", line 162, in _render
    return self.nodelist.render(context)
  File "C:\Users\Zhixuan\AppData\Local\Programs\Python\Python39\lib\site-packages\django\template\base.py", line 938, in render
    bit = node.render_annotated(context)
  File "C:\Users\Zhixuan\AppData\Local\Programs\Python\Python39\lib\site-packages\django\template\base.py", line 905, in render_annotated
    return self.render(context)
  File "C:\Users\Zhixuan\AppData\Local\Programs\Python\Python39\lib\site-packages\django\template\loader_tags.py", line 62, in render
    result = block.nodelist.render(context)
  File "C:\Users\Zhixuan\AppData\Local\Programs\Python\Python39\lib\site-packages\django\template\base.py", line 938, in render
    bit = node.render_annotated(context)
  File "C:\Users\Zhixuan\AppData\Local\Programs\Python\Python39\lib\site-packages\django\template\base.py", line 905, in render_annotated
    return self.render(context)
  File "C:\Users\Zhixuan\AppData\Local\Programs\Python\Python39\lib\site-packages\django\template\defaulttags.py", line 312, in render
    return nodelist.render(context)
  File "C:\Users\Zhixuan\AppData\Local\Programs\Python\Python39\lib\site-packages\django\template\base.py", line 938, in render
    bit = node.render_annotated(context)
  File "C:\Users\Zhixuan\AppData\Local\Programs\Python\Python39\lib\site-packages\django\template\base.py", line 905, in render_annotated
    return self.render(context)
  File "C:\Users\Zhixuan\AppData\Local\Programs\Python\Python39\lib\site-packages\django\template\defaulttags.py", line 446, in render
    url = reverse(view_name, args=args, kwargs=kwargs, current_app=current_app)
  File "C:\Users\Zhixuan\AppData\Local\Programs\Python\Python39\lib\site-packages\django\urls\base.py", line 86, in reverse
    return resolver._reverse_with_prefix(view, prefix, *args, **kwargs)
  File "C:\Users\Zhixuan\AppData\Local\Programs\Python\Python39\lib\site-packages\django\urls\resolvers.py", line 694, in _reverse_with_prefix
    raise NoReverseMatch(msg)
django.urls.exceptions.NoReverseMatch: Reverse for 'nextindex' with arguments '('',)' not found. 1 pattern(s) tried: ['(?P<pagenumber>[0-9]+)/nextin$']
2021-06-10 15:55:47,970 [ERROR] django.request: Internal Server Error: /1/nextstall
Traceback (most recent call last):
  File "C:\Users\Zhixuan\AppData\Local\Programs\Python\Python39\lib\site-packages\django\utils\datastructures.py", line 76, in __getitem__
    list_ = super().__getitem__(key)
KeyError: 'stalltype'

During handling of the above exception, another exception occurred:

Traceback (most recent call last):
  File "C:\Users\Zhixuan\AppData\Local\Programs\Python\Python39\lib\site-packages\django\core\handlers\exception.py", line 47, in inner
    response = get_response(request)
  File "C:\Users\Zhixuan\AppData\Local\Programs\Python\Python39\lib\site-packages\django\core\handlers\base.py", line 181, in _get_response
    response = wrapped_callback(request, *callback_args, **callback_kwargs)
  File "C:\Users\Zhixuan\Documents\GitHub\savethehawkers\project\views.py", line 294, in nextstall
    stalltypes = request.POST["stalltype"]
  File "C:\Users\Zhixuan\AppData\Local\Programs\Python\Python39\lib\site-packages\django\utils\datastructures.py", line 78, in __getitem__
    raise MultiValueDictKeyError(key)
django.utils.datastructures.MultiValueDictKeyError: 'stalltype'
